[2025-07-15T19:50:37.424+0000] {taskinstance.py:1103} INFO - Dependencies all met for dep_context=non-requeueable deps ti=<TaskInstance: etl_success_sensor.delay_task manual__2025-07-15T19:50:33.603735+00:00 [queued]>
[2025-07-15T19:50:37.428+0000] {taskinstance.py:1103} INFO - Dependencies all met for dep_context=requeueable deps ti=<TaskInstance: etl_success_sensor.delay_task manual__2025-07-15T19:50:33.603735+00:00 [queued]>
[2025-07-15T19:50:37.428+0000] {taskinstance.py:1308} INFO - Starting attempt 1 of 2
[2025-07-15T19:50:37.434+0000] {taskinstance.py:1327} INFO - Executing <Task(PythonOperator): delay_task> on 2025-07-15 19:50:33.603735+00:00
[2025-07-15T19:50:37.436+0000] {standard_task_runner.py:57} INFO - Started process 4853 to run task
[2025-07-15T19:50:37.437+0000] {standard_task_runner.py:84} INFO - Running: ['***', 'tasks', 'run', 'etl_success_sensor', 'delay_task', 'manual__2025-07-15T19:50:33.603735+00:00', '--job-id', '103', '--raw', '--subdir', 'DAGS_FOLDER/success_sensor_dag.py', '--cfg-path', '/tmp/tmpr15nf5nj']
[2025-07-15T19:50:37.438+0000] {standard_task_runner.py:85} INFO - Job 103: Subtask delay_task
[2025-07-15T19:50:37.456+0000] {task_command.py:410} INFO - Running <TaskInstance: etl_success_sensor.delay_task manual__2025-07-15T19:50:33.603735+00:00 [running]> on host 1e79179934e4
[2025-07-15T19:50:37.491+0000] {taskinstance.py:1547} INFO - Exporting env vars: AIRFLOW_CTX_DAG_OWNER='***' AIRFLOW_CTX_DAG_ID='etl_success_sensor' AIRFLOW_CTX_TASK_ID='delay_task' AIRFLOW_CTX_EXECUTION_DATE='2025-07-15T19:50:33.603735+00:00' AIRFLOW_CTX_TRY_NUMBER='1' AIRFLOW_CTX_DAG_RUN_ID='manual__2025-07-15T19:50:33.603735+00:00'
[2025-07-15T19:50:37.491+0000] {logging_mixin.py:150} INFO - Delaying for 1 minute...
[2025-07-15T19:51:32.871+0000] {local_task_job_runner.py:292} WARNING - State of this instance has been externally set to None. Terminating instance.
[2025-07-15T19:51:32.873+0000] {process_utils.py:135} INFO - Sending Signals.SIGTERM to group 4853. PIDs of all processes in the group: [4853]
[2025-07-15T19:51:32.873+0000] {process_utils.py:86} INFO - Sending the signal Signals.SIGTERM to group 4853
[2025-07-15T19:51:32.873+0000] {taskinstance.py:1517} ERROR - Received SIGTERM. Terminating subprocesses.
[2025-07-15T19:51:32.878+0000] {taskinstance.py:1824} ERROR - Task failed with exception
Traceback (most recent call last):
  File "/home/airflow/.local/lib/python3.7/site-packages/airflow/operators/python.py", line 181, in execute
    return_value = self.execute_callable()
  File "/home/airflow/.local/lib/python3.7/site-packages/airflow/operators/python.py", line 198, in execute_callable
    return self.python_callable(*self.op_args, **self.op_kwargs)
  File "/opt/airflow/dags/success_sensor_dag.py", line 54, in delay_task
    time.sleep(LOOK_BACK_HOURS * 3600)
  File "/home/airflow/.local/lib/python3.7/site-packages/airflow/models/taskinstance.py", line 1519, in signal_handler
    raise AirflowException("Task received SIGTERM signal")
airflow.exceptions.AirflowException: Task received SIGTERM signal
[2025-07-15T19:51:32.881+0000] {taskinstance.py:1350} INFO - Marking task as FAILED. dag_id=etl_success_sensor, task_id=delay_task, execution_date=20250715T195033, start_date=20250715T195037, end_date=20250715T195132
[2025-07-15T19:51:32.887+0000] {standard_task_runner.py:109} ERROR - Failed to execute job 103 for task delay_task ((psycopg2.errors.ForeignKeyViolation) insert or update on table "task_fail" violates foreign key constraint "task_fail_ti_fkey"
DETAIL:  Key (dag_id, task_id, run_id, map_index)=(etl_success_sensor, delay_task, manual__2025-07-15T19:50:33.603735+00:00, -1) is not present in table "task_instance".

[SQL: INSERT INTO task_fail (task_id, dag_id, run_id, map_index, start_date, end_date, duration) VALUES (%(task_id)s, %(dag_id)s, %(run_id)s, %(map_index)s, %(start_date)s, %(end_date)s, %(duration)s) RETURNING task_fail.id]
[parameters: {'task_id': 'delay_task', 'dag_id': 'etl_success_sensor', 'run_id': 'manual__2025-07-15T19:50:33.603735+00:00', 'map_index': -1, 'start_date': datetime.datetime(2025, 7, 15, 19, 50, 37, 424666, tzinfo=Timezone('UTC')), 'end_date': datetime.datetime(2025, 7, 15, 19, 51, 32, 881386, tzinfo=Timezone('UTC')), 'duration': 55}]
(Background on this error at: https://sqlalche.me/e/14/gkpj); 4853)
[2025-07-15T19:51:32.905+0000] {process_utils.py:79} INFO - Process psutil.Process(pid=4853, status='terminated', exitcode=1, started='19:50:37') (4853) terminated with exit code 1
