[2025-07-16T20:47:08.764+0000] {taskinstance.py:1103} INFO - Dependencies all met for dep_context=non-requeueable deps ti=<TaskInstance: uploader_dag.upload_task manual__2025-07-16T20:47:08.344565+00:00 [queued]>
[2025-07-16T20:47:08.770+0000] {taskinstance.py:1103} INFO - Dependencies all met for dep_context=requeueable deps ti=<TaskInstance: uploader_dag.upload_task manual__2025-07-16T20:47:08.344565+00:00 [queued]>
[2025-07-16T20:47:08.770+0000] {taskinstance.py:1308} INFO - Starting attempt 1 of 2
[2025-07-16T20:47:08.777+0000] {taskinstance.py:1327} INFO - Executing <Task(PythonOperator): upload_task> on 2025-07-16 20:47:08.344565+00:00
[2025-07-16T20:47:08.779+0000] {standard_task_runner.py:57} INFO - Started process 2524 to run task
[2025-07-16T20:47:08.780+0000] {standard_task_runner.py:84} INFO - Running: ['***', 'tasks', 'run', 'uploader_dag', 'upload_task', 'manual__2025-07-16T20:47:08.344565+00:00', '--job-id', '437', '--raw', '--subdir', 'DAGS_FOLDER/uploader_dag.py', '--cfg-path', '/tmp/tmpd6oygh0e']
[2025-07-16T20:47:08.783+0000] {standard_task_runner.py:85} INFO - Job 437: Subtask upload_task
[2025-07-16T20:47:08.802+0000] {task_command.py:410} INFO - Running <TaskInstance: uploader_dag.upload_task manual__2025-07-16T20:47:08.344565+00:00 [running]> on host 66ed94c0a57f
[2025-07-16T20:47:08.839+0000] {taskinstance.py:1547} INFO - Exporting env vars: AIRFLOW_CTX_DAG_OWNER='***' AIRFLOW_CTX_DAG_ID='uploader_dag' AIRFLOW_CTX_TASK_ID='upload_task' AIRFLOW_CTX_EXECUTION_DATE='2025-07-16T20:47:08.344565+00:00' AIRFLOW_CTX_TRY_NUMBER='1' AIRFLOW_CTX_DAG_RUN_ID='manual__2025-07-16T20:47:08.344565+00:00'
[2025-07-16T20:47:08.839+0000] {logging_mixin.py:150} INFO - Received conf: {}
[2025-07-16T20:47:08.840+0000] {taskinstance.py:1824} ERROR - Task failed with exception
Traceback (most recent call last):
  File "/home/airflow/.local/lib/python3.7/site-packages/airflow/operators/python.py", line 181, in execute
    return_value = self.execute_callable()
  File "/home/airflow/.local/lib/python3.7/site-packages/airflow/operators/python.py", line 198, in execute_callable
    return self.python_callable(*self.op_args, **self.op_kwargs)
  File "/opt/airflow/dags/uploader_dag.py", line 33, in upload_artifacts
    message = TriggerConfig.parse_obj(conf)
  File "/home/airflow/.local/lib/python3.7/site-packages/pydantic/main.py", line 526, in parse_obj
    return cls(**obj)
  File "/home/airflow/.local/lib/python3.7/site-packages/pydantic/main.py", line 341, in __init__
    raise validation_error
pydantic.error_wrappers.ValidationError: 3 validation errors for TriggerConfig
dag_id
  field required (type=value_error.missing)
command
  field required (type=value_error.missing)
date_time
  field required (type=value_error.missing)
[2025-07-16T20:47:08.844+0000] {taskinstance.py:1350} INFO - Marking task as UP_FOR_RETRY. dag_id=uploader_dag, task_id=upload_task, execution_date=20250716T204708, start_date=20250716T204708, end_date=20250716T204708
[2025-07-16T20:47:08.849+0000] {standard_task_runner.py:109} ERROR - Failed to execute job 437 for task upload_task (3 validation errors for TriggerConfig
dag_id
  field required (type=value_error.missing)
command
  field required (type=value_error.missing)
date_time
  field required (type=value_error.missing); 2524)
[2025-07-16T20:47:08.880+0000] {local_task_job_runner.py:225} INFO - Task exited with return code 1
[2025-07-16T20:47:08.889+0000] {taskinstance.py:2653} INFO - 0 downstream tasks scheduled from follow-on schedule check
