[2025-07-16T09:20:26.722+0000] {taskinstance.py:1103} INFO - Dependencies all met for dep_context=non-requeueable deps ti=<TaskInstance: uploader_dag.upload_task manual__2025-07-16T09:13:40.510882+00:00 [queued]>
[2025-07-16T09:20:26.727+0000] {taskinstance.py:1103} INFO - Dependencies all met for dep_context=requeueable deps ti=<TaskInstance: uploader_dag.upload_task manual__2025-07-16T09:13:40.510882+00:00 [queued]>
[2025-07-16T09:20:26.727+0000] {taskinstance.py:1308} INFO - Starting attempt 1 of 2
[2025-07-16T09:20:26.733+0000] {taskinstance.py:1327} INFO - Executing <Task(PythonOperator): upload_task> on 2025-07-16 09:13:40.510882+00:00
[2025-07-16T09:20:26.735+0000] {standard_task_runner.py:57} INFO - Started process 3428 to run task
[2025-07-16T09:20:26.736+0000] {standard_task_runner.py:84} INFO - Running: ['***', 'tasks', 'run', 'uploader_dag', 'upload_task', 'manual__2025-07-16T09:13:40.510882+00:00', '--job-id', '114', '--raw', '--subdir', 'DAGS_FOLDER/uploader_dag.py', '--cfg-path', '/tmp/tmpnjw9hqq1']
[2025-07-16T09:20:26.739+0000] {standard_task_runner.py:85} INFO - Job 114: Subtask upload_task
[2025-07-16T09:20:26.760+0000] {task_command.py:410} INFO - Running <TaskInstance: uploader_dag.upload_task manual__2025-07-16T09:13:40.510882+00:00 [running]> on host 0f12c04aebf5
[2025-07-16T09:20:26.798+0000] {taskinstance.py:1547} INFO - Exporting env vars: AIRFLOW_CTX_DAG_OWNER='***' AIRFLOW_CTX_DAG_ID='uploader_dag' AIRFLOW_CTX_TASK_ID='upload_task' AIRFLOW_CTX_EXECUTION_DATE='2025-07-16T09:13:40.510882+00:00' AIRFLOW_CTX_TRY_NUMBER='1' AIRFLOW_CTX_DAG_RUN_ID='manual__2025-07-16T09:13:40.510882+00:00'
[2025-07-16T09:20:26.798+0000] {taskinstance.py:1824} ERROR - Task failed with exception
Traceback (most recent call last):
  File "/home/airflow/.local/lib/python3.7/site-packages/airflow/operators/python.py", line 181, in execute
    return_value = self.execute_callable()
  File "/home/airflow/.local/lib/python3.7/site-packages/airflow/operators/python.py", line 198, in execute_callable
    return self.python_callable(*self.op_args, **self.op_kwargs)
  File "/opt/airflow/dags/uploader_dag.py", line 30, in upload_artifacts
    message = TriggerConfig(**context['dag_run'].conf)
TypeError: __init__() missing 1 required positional argument: 'date_time'
[2025-07-16T09:20:26.801+0000] {taskinstance.py:1350} INFO - Marking task as UP_FOR_RETRY. dag_id=uploader_dag, task_id=upload_task, execution_date=20250716T091340, start_date=20250716T092026, end_date=20250716T092026
[2025-07-16T09:20:26.806+0000] {standard_task_runner.py:109} ERROR - Failed to execute job 114 for task upload_task (__init__() missing 1 required positional argument: 'date_time'; 3428)
[2025-07-16T09:20:26.834+0000] {local_task_job_runner.py:225} INFO - Task exited with return code 1
[2025-07-16T09:20:26.843+0000] {taskinstance.py:2653} INFO - 0 downstream tasks scheduled from follow-on schedule check
