[2025-07-16T09:07:43.293+0000] {taskinstance.py:1103} INFO - Dependencies all met for dep_context=non-requeueable deps ti=<TaskInstance: uploader_dag.upload_task manual__2025-07-16T09:07:42.287633+00:00 [queued]>
[2025-07-16T09:07:43.297+0000] {taskinstance.py:1103} INFO - Dependencies all met for dep_context=requeueable deps ti=<TaskInstance: uploader_dag.upload_task manual__2025-07-16T09:07:42.287633+00:00 [queued]>
[2025-07-16T09:07:43.297+0000] {taskinstance.py:1308} INFO - Starting attempt 1 of 2
[2025-07-16T09:07:43.303+0000] {taskinstance.py:1327} INFO - Executing <Task(PythonOperator): upload_task> on 2025-07-16 09:07:42.287633+00:00
[2025-07-16T09:07:43.305+0000] {standard_task_runner.py:57} INFO - Started process 1949 to run task
[2025-07-16T09:07:43.306+0000] {standard_task_runner.py:84} INFO - Running: ['***', 'tasks', 'run', 'uploader_dag', 'upload_task', 'manual__2025-07-16T09:07:42.287633+00:00', '--job-id', '91', '--raw', '--subdir', 'DAGS_FOLDER/uploader_dag.py', '--cfg-path', '/tmp/tmpn3iih1t5']
[2025-07-16T09:07:43.309+0000] {standard_task_runner.py:85} INFO - Job 91: Subtask upload_task
[2025-07-16T09:07:43.328+0000] {task_command.py:410} INFO - Running <TaskInstance: uploader_dag.upload_task manual__2025-07-16T09:07:42.287633+00:00 [running]> on host 0f12c04aebf5
[2025-07-16T09:07:43.361+0000] {taskinstance.py:1547} INFO - Exporting env vars: AIRFLOW_CTX_DAG_OWNER='***' AIRFLOW_CTX_DAG_ID='uploader_dag' AIRFLOW_CTX_TASK_ID='upload_task' AIRFLOW_CTX_EXECUTION_DATE='2025-07-16T09:07:42.287633+00:00' AIRFLOW_CTX_TRY_NUMBER='1' AIRFLOW_CTX_DAG_RUN_ID='manual__2025-07-16T09:07:42.287633+00:00'
[2025-07-16T09:07:43.364+0000] {taskinstance.py:1824} ERROR - Task failed with exception
Traceback (most recent call last):
  File "/home/airflow/.local/lib/python3.7/site-packages/airflow/operators/python.py", line 181, in execute
    return_value = self.execute_callable()
  File "/home/airflow/.local/lib/python3.7/site-packages/airflow/operators/python.py", line 198, in execute_callable
    return self.python_callable(*self.op_args, **self.op_kwargs)
  File "/opt/airflow/dags/uploader_dag.py", line 35, in upload_artifacts
    current_time = datetime.now(tz=datetime.timezone.utc)
AttributeError: type object 'datetime.datetime' has no attribute 'timezone'
[2025-07-16T09:07:43.367+0000] {taskinstance.py:1350} INFO - Marking task as UP_FOR_RETRY. dag_id=uploader_dag, task_id=upload_task, execution_date=20250716T090742, start_date=20250716T090743, end_date=20250716T090743
[2025-07-16T09:07:43.372+0000] {standard_task_runner.py:109} ERROR - Failed to execute job 91 for task upload_task (type object 'datetime.datetime' has no attribute 'timezone'; 1949)
[2025-07-16T09:07:43.406+0000] {local_task_job_runner.py:225} INFO - Task exited with return code 1
[2025-07-16T09:07:43.415+0000] {taskinstance.py:2653} INFO - 0 downstream tasks scheduled from follow-on schedule check
