[2025-07-16T21:14:23.752+0000] {taskinstance.py:1103} INFO - Dependencies all met for dep_context=non-requeueable deps ti=<TaskInstance: dbt_build_monolith.fail_task scheduled__2025-07-16T21:13:11.059887+00:00 [queued]>
[2025-07-16T21:14:23.756+0000] {taskinstance.py:1103} INFO - Dependencies all met for dep_context=requeueable deps ti=<TaskInstance: dbt_build_monolith.fail_task scheduled__2025-07-16T21:13:11.059887+00:00 [queued]>
[2025-07-16T21:14:23.757+0000] {taskinstance.py:1308} INFO - Starting attempt 1 of 1
[2025-07-16T21:14:23.762+0000] {taskinstance.py:1327} INFO - Executing <Task(PythonOperator): fail_task> on 2025-07-16 21:13:11.059887+00:00
[2025-07-16T21:14:23.764+0000] {standard_task_runner.py:57} INFO - Started process 5709 to run task
[2025-07-16T21:14:23.766+0000] {standard_task_runner.py:84} INFO - Running: ['***', 'tasks', 'run', 'dbt_build_monolith', 'fail_task', 'scheduled__2025-07-16T21:13:11.059887+00:00', '--job-id', '539', '--raw', '--subdir', 'DAGS_FOLDER/dbt_build_monolith.py', '--cfg-path', '/tmp/tmp7ylevm1u']
[2025-07-16T21:14:23.767+0000] {standard_task_runner.py:85} INFO - Job 539: Subtask fail_task
[2025-07-16T21:14:23.784+0000] {task_command.py:410} INFO - Running <TaskInstance: dbt_build_monolith.fail_task scheduled__2025-07-16T21:13:11.059887+00:00 [running]> on host 66ed94c0a57f
[2025-07-16T21:14:23.820+0000] {taskinstance.py:1547} INFO - Exporting env vars: AIRFLOW_CTX_DAG_OWNER='***' AIRFLOW_CTX_DAG_ID='dbt_build_monolith' AIRFLOW_CTX_TASK_ID='fail_task' AIRFLOW_CTX_EXECUTION_DATE='2025-07-16T21:13:11.059887+00:00' AIRFLOW_CTX_TRY_NUMBER='1' AIRFLOW_CTX_DAG_RUN_ID='scheduled__2025-07-16T21:13:11.059887+00:00'
[2025-07-16T21:14:23.821+0000] {logging_mixin.py:150} INFO - Executing fail task - Failure path
[2025-07-16T21:14:23.821+0000] {logging_mixin.py:150} INFO - Current time: 2025-07-16 21:14:23.821186
[2025-07-16T21:14:23.821+0000] {taskinstance.py:1824} ERROR - Task failed with exception
Traceback (most recent call last):
  File "/home/airflow/.local/lib/python3.7/site-packages/airflow/operators/python.py", line 181, in execute
    return_value = self.execute_callable()
  File "/home/airflow/.local/lib/python3.7/site-packages/airflow/operators/python.py", line 198, in execute_callable
    return self.python_callable(*self.op_args, **self.op_kwargs)
  File "/opt/airflow/dags/dbt_build_monolith.py", line 55, in fail_task
    raise ValueError("This task is designed to fail on even minutes")
ValueError: This task is designed to fail on even minutes
[2025-07-16T21:14:23.824+0000] {taskinstance.py:1350} INFO - Marking task as FAILED. dag_id=dbt_build_monolith, task_id=fail_task, execution_date=20250716T211311, start_date=20250716T211423, end_date=20250716T211423
[2025-07-16T21:14:23.828+0000] {standard_task_runner.py:109} ERROR - Failed to execute job 539 for task fail_task (This task is designed to fail on even minutes; 5709)
[2025-07-16T21:14:23.863+0000] {local_task_job_runner.py:225} INFO - Task exited with return code 1
[2025-07-16T21:14:23.871+0000] {taskinstance.py:2653} INFO - 0 downstream tasks scheduled from follow-on schedule check
