[2025-07-16T09:19:24.295+0000] {taskinstance.py:1103} INFO - Dependencies all met for dep_context=non-requeueable deps ti=<TaskInstance: uploader_dag.upload_task manual__2025-07-16T09:09:54.519816+00:00 [queued]>
[2025-07-16T09:19:24.299+0000] {taskinstance.py:1103} INFO - Dependencies all met for dep_context=requeueable deps ti=<TaskInstance: uploader_dag.upload_task manual__2025-07-16T09:09:54.519816+00:00 [queued]>
[2025-07-16T09:19:24.299+0000] {taskinstance.py:1308} INFO - Starting attempt 3 of 4
[2025-07-16T09:19:24.305+0000] {taskinstance.py:1327} INFO - Executing <Task(PythonOperator): upload_task> on 2025-07-16 09:09:54.519816+00:00
[2025-07-16T09:19:24.307+0000] {standard_task_runner.py:57} INFO - Started process 3311 to run task
[2025-07-16T09:19:24.308+0000] {standard_task_runner.py:84} INFO - Running: ['***', 'tasks', 'run', 'uploader_dag', 'upload_task', 'manual__2025-07-16T09:09:54.519816+00:00', '--job-id', '112', '--raw', '--subdir', 'DAGS_FOLDER/uploader_dag.py', '--cfg-path', '/tmp/tmpjffg5vjd']
[2025-07-16T09:19:24.311+0000] {standard_task_runner.py:85} INFO - Job 112: Subtask upload_task
[2025-07-16T09:19:24.331+0000] {task_command.py:410} INFO - Running <TaskInstance: uploader_dag.upload_task manual__2025-07-16T09:09:54.519816+00:00 [running]> on host 0f12c04aebf5
[2025-07-16T09:19:24.363+0000] {taskinstance.py:1547} INFO - Exporting env vars: AIRFLOW_CTX_DAG_OWNER='***' AIRFLOW_CTX_DAG_ID='uploader_dag' AIRFLOW_CTX_TASK_ID='upload_task' AIRFLOW_CTX_EXECUTION_DATE='2025-07-16T09:09:54.519816+00:00' AIRFLOW_CTX_TRY_NUMBER='3' AIRFLOW_CTX_DAG_RUN_ID='manual__2025-07-16T09:09:54.519816+00:00'
[2025-07-16T09:19:24.364+0000] {taskinstance.py:1824} ERROR - Task failed with exception
Traceback (most recent call last):
  File "/home/airflow/.local/lib/python3.7/site-packages/airflow/operators/python.py", line 181, in execute
    return_value = self.execute_callable()
  File "/home/airflow/.local/lib/python3.7/site-packages/airflow/operators/python.py", line 198, in execute_callable
    return self.python_callable(*self.op_args, **self.op_kwargs)
  File "/opt/airflow/dags/uploader_dag.py", line 30, in upload_artifacts
    message = TriggerConfig(**context['dag_run'].conf)
TypeError: __init__() missing 1 required positional argument: 'date_time'
[2025-07-16T09:19:24.367+0000] {taskinstance.py:1350} INFO - Marking task as UP_FOR_RETRY. dag_id=uploader_dag, task_id=upload_task, execution_date=20250716T090954, start_date=20250716T091924, end_date=20250716T091924
[2025-07-16T09:19:24.371+0000] {standard_task_runner.py:109} ERROR - Failed to execute job 112 for task upload_task (__init__() missing 1 required positional argument: 'date_time'; 3311)
[2025-07-16T09:19:24.409+0000] {local_task_job_runner.py:225} INFO - Task exited with return code 1
[2025-07-16T09:19:24.418+0000] {taskinstance.py:2653} INFO - 0 downstream tasks scheduled from follow-on schedule check
